<<<<<<< HEAD
<?xml version="1.0" ?>
<robot name="rb1_robot">

  <!-- Specify Gazebo color for the base_link -->
  <gazebo reference="base_link">
    <visual>
      <material> <!-- Black -->
        <ambient>0.1 0.1 0.1 1.0</ambient>
        <diffuse>0.1 0.1 0.1 1.0</diffuse>
        <specular>0.0 0.0 0.0 1.0</specular>
        <emissive>0.0 0.0 0.0 1.0</emissive>
      </material>
    </visual>
  </gazebo>

  <!-- Gazebo friction and material properties for wheels/casters -->
  <gazebo reference="left_wheel">
    <collision>
      <surface>
        <friction>
          <ode>
            <mu>0.0</mu>
            <mu2>0.0</mu2>
          </ode>
        </friction>
      </surface>
    </collision>
  </gazebo>

  <gazebo reference="right_wheel">
    <collision>
      <surface>
        <friction>
          <ode>
            <mu>0.0</mu>
            <mu2>0.0</mu2>
          </ode>
        </friction>
      </surface>
    </collision>
  </gazebo>

  <gazebo reference="front_caster">
    <collision>
      <surface>
        <friction>
          <ode>
            <mu>0.0</mu>
            <mu2>0.0</mu2>
          </ode>
        </friction>
      </surface>
    </collision>
  </gazebo>

  <gazebo reference="back_caster">
    <collision>
      <surface>
        <friction>
          <ode>
            <mu>0.0</mu>
            <mu2>0.0</mu2>
          </ode>
        </friction>
      </surface>
    </collision>
  </gazebo>

  <!-- Define materials for visualization (rgba values 0..1) -->
  <material name="blue">
=======
<?xml version="1.0"?>
<robot name="rb1_robot">

  <!-- ===== Materials ===== -->
  <material name="blue">
    <!-- rgba values must be 0..1 -->
>>>>>>> spawnrb2
    <color rgba="0 0 1 1"/>
  </material>

  <material name="gray">
    <color rgba="0.40 0.40 0.40 1"/>
  </material>

  <material name="red">
    <color rgba="1 0 0 1"/>
  </material>

  <material name="black">
    <color rgba="0 0 0 1"/>
  </material>

<<<<<<< HEAD
  <!-- Base footprint link -->
  <link name="base_footprint"/>

  <!-- Joint connecting base_link and base_footprint -->
=======
  <!-- ===== Base footprint (self-closing link) ===== -->
  <link name="base_footprint"/>

  <!-- ===== Joint connecting base_footprint -> base_link ===== -->
>>>>>>> spawnrb2
  <joint name="base_link_plate_joint" type="fixed">
    <parent link="base_footprint"/>
    <child link="base_link"/>
    <origin xyz="0 0 0.15" rpy="0 0 0"/>
  </joint>

<<<<<<< HEAD
  <!-- Base link -->
=======
  <!-- ===== Base link ===== -->
>>>>>>> spawnrb2
  <link name="base_link">
    <inertial>
      <origin xyz="0 0 0" rpy="0 0 0"/>
      <mass value="23.1"/>
      <inertia ixx="0.5341875" ixy="0.0" ixz="0.0" iyy="0.5341875" iyz="0.0" izz="0.7225"/>
    </inertial>

    <visual>
      <origin xyz="0 0 0" rpy="0 0 0"/>
      <geometry>
        <cylinder radius="0.25" length="0.30"/>
      </geometry>
<<<<<<< HEAD
      <material name="blue"/>
=======
      <material name="gray"/>
>>>>>>> spawnrb2
    </visual>

    <collision>
      <origin xyz="0 0 0" rpy="0 0 0"/>
      <geometry>
        <cylinder radius="0.25" length="0.30"/>
      </geometry>
    </collision>
  </link>

<<<<<<< HEAD
  <!-- Left wheel link -->
=======
  <!-- ===== Left wheel ===== -->
>>>>>>> spawnrb2
  <link name="left_wheel">
    <inertial>
      <origin xyz="0 0 0" rpy="0 0 0"/>
      <mass value="0.5"/>
      <inertia ixx="0.00014479" ixy="0.0" ixz="0.0" iyy="0.00015625" iyz="0.0" izz="0.00014479"/>
    </inertial>

    <visual>
      <origin xyz="0 0 0" rpy="-1.5708 0 0"/>
      <geometry>
        <cylinder radius="0.025" length="0.04"/>
      </geometry>
      <material name="black"/>
    </visual>

    <collision>
      <origin xyz="0 0 0" rpy="-1.5708 0 0"/>
      <geometry>
        <cylinder radius="0.025" length="0.04"/>
      </geometry>
    </collision>
  </link>

<<<<<<< HEAD
  <!-- Joint connecting base_link and left_wheel -->
=======
>>>>>>> spawnrb2
  <joint name="base_link_left_wheel_joint" type="continuous">
    <parent link="base_link"/>
    <child link="left_wheel"/>
    <origin xyz="0.0 0.2 -0.15" rpy="0 0 0"/>
    <axis xyz="0 1 0"/>
  </joint>

<<<<<<< HEAD
  <!-- Right wheel link -->
=======
  <!-- ===== Right wheel ===== -->
>>>>>>> spawnrb2
  <link name="right_wheel">
    <inertial>
      <origin xyz="0 0 0" rpy="0 0 0"/>
      <mass value="0.5"/>
      <inertia ixx="0.00014479" ixy="0.0" ixz="0.0" iyy="0.00015625" iyz="0.0" izz="0.00014479"/>
    </inertial>

    <visual>
      <origin xyz="0 0 0" rpy="-1.5708 0 0"/>
      <geometry>
        <cylinder radius="0.025" length="0.04"/>
      </geometry>
<<<<<<< HEAD
=======
      <material name="black"/>
>>>>>>> spawnrb2
    </visual>

    <collision>
      <origin xyz="0 0 0" rpy="-1.5708 0 0"/>
      <geometry>
        <cylinder radius="0.025" length="0.04"/>
      </geometry>
    </collision>
  </link>

<<<<<<< HEAD
  <!-- Joint connecting base_link and right_wheel -->
=======
>>>>>>> spawnrb2
  <joint name="base_link_right_wheel_joint" type="continuous">
    <parent link="base_link"/>
    <child link="right_wheel"/>
    <origin xyz="0.0 -0.2 -0.15" rpy="0 0 0"/>
    <axis xyz="0 1 0"/>
  </joint>

<<<<<<< HEAD
  <!-- Front caster -->
=======
  <!-- ===== Front caster ===== -->
>>>>>>> spawnrb2
  <link name="front_caster">
    <inertial>
      <origin xyz="0 0 0" rpy="0 0 0"/>
      <mass value="0.2"/>
      <inertia ixx="0.00003792" ixy="0.0" ixz="0.0" iyy="0.0000625" iyz="0.0" izz="0.00003792"/>
    </inertial>

    <visual>
      <origin xyz="0 0 0" rpy="-1.5708 0 0"/>
      <geometry>
        <cylinder radius="0.025" length="0.02"/>
      </geometry>
<<<<<<< HEAD
=======
      <material name="gray"/>
>>>>>>> spawnrb2
    </visual>

    <collision>
      <origin xyz="0 0 0" rpy="-1.5708 0 0"/>
      <geometry>
        <cylinder radius="0.025" length="0.02"/>
      </geometry>
    </collision>
  </link>

<<<<<<< HEAD
  <!-- Joint connecting base_link and front_caster -->
  <joint name="base_link_front_caster_joint" type="continuous">
    <parent link="base_link"/>
    <child link="front_caster"/>
    <origin xyz="-0.1 0.0 -0.15" rpy="0 0 0"/>
    <axis xyz="0 1 0"/>
  </joint>

  <!-- Back caster -->
=======
  <joint name="base_link_front_caster_joint" type="fixed">
    <parent link="base_link"/>
    <child link="front_caster"/>
    <origin xyz="-0.1 0.0 -0.15" rpy="0 0 0"/>
  </joint>

  <!-- ===== Back caster ===== -->
>>>>>>> spawnrb2
  <link name="back_caster">
    <inertial>
      <origin xyz="0 0 0" rpy="0 0 0"/>
      <mass value="0.2"/>
      <inertia ixx="0.00003792" ixy="0.0" ixz="0.0" iyy="0.0000625" iyz="0.0" izz="0.00003792"/>
    </inertial>

    <visual>
      <origin xyz="0 0 0" rpy="-1.5708 0 0"/>
      <geometry>
        <cylinder radius="0.025" length="0.02"/>
      </geometry>
<<<<<<< HEAD
=======
      <material name="gray"/>
>>>>>>> spawnrb2
    </visual>

    <collision>
      <origin xyz="0 0 0" rpy="-1.5708 0 0"/>
      <geometry>
        <cylinder radius="0.025" length="0.02"/>
      </geometry>
    </collision>
  </link>

<<<<<<< HEAD
  <!-- Joint connecting base_link and back_caster -->
  <joint name="base_link_back_caster_joint" type="continuous">
    <parent link="base_link"/>
    <child link="back_caster"/>
    <origin xyz="0.1 0.0 -0.15" rpy="0 0 0"/>
    <axis xyz="0 1 0"/>
  </joint>

  <!-- Link representing the front laser scanner -->
  <link name="front_laser"/>

  <!-- Differential Drive Plugin -->
=======
  <joint name="base_link_back_caster_joint" type="fixed">
    <parent link="base_link"/>
    <child link="back_caster"/>
    <origin xyz="0.1 0.0 -0.15" rpy="0 0 0"/>
  </joint>

  <!-- ===== Front laser link (visual + sensor for Gazebo Sim) ===== -->
  <link name="front_laser">
    <inertial>
      <origin xyz="0 0 0" rpy="0 0 0"/>
      <mass value="0.5"/>
      <inertia ixx="0.000252666666667" ixy="0" ixz="0" iyy="0.000252666666667" iyz="0" izz="0.0005"/>
    </inertial>

    <visual>
      <origin xyz="0 0 0" rpy="0 0 0"/>
      <geometry>
        <cylinder radius="0.05" length="0.10"/>
      </geometry>
      <material name="red"/>
    </visual>

    <collision>
      <origin xyz="0 0 0" rpy="0 0 0"/>
      <geometry>
        <cylinder radius="0.05" length="0.10"/>
      </geometry>
    </collision>

    <!-- Gazebo Sim sensor (gpu_lidar) — publishes to /laser/scan -->
    <gazebo>
      <sensor name="front_laser_sensor" type="gpu_lidar">
        <update_rate>10</update_rate>
        <topic>laser/scan</topic>
        <ray>
          <scan>
            <horizontal>
              <samples>360</samples>
              <resolution>1</resolution>
              <min_angle>-3.14159</min_angle>
              <max_angle>3.14159</max_angle>
            </horizontal>
          </scan>
          <range>
            <min>0.12</min>
            <max>8.0</max>
            <resolution>0.01</resolution>
          </range>
          <noise>
            <type>gaussian</type>
            <mean>0.0</mean>
            <stddev>0.01</stddev>
          </noise>
        </ray>
      </sensor>
    </gazebo>
  </link>

  <joint name="base_link_front_laser_joint" type="fixed">
    <parent link="base_link"/>
    <child link="front_laser"/>
    <origin xyz="0.8 0 0.3" rpy="0 0 0"/>
  </joint>

  <!-- ===== Optional visual 'link' for laser geometry (kept removed to avoid duplicates) ===== -->

  <!-- ===== Differential drive plugin for Gazebo Sim (Ignition) ===== -->
>>>>>>> spawnrb2
  <gazebo>
    <plugin
      filename="libignition-gazebo-diff-drive-system.so"
      name="ignition::gazebo::systems::DiffDrive">
<<<<<<< HEAD
      <left_joint>base_link_left_wheel_joint</left_joint>
      <right_joint>base_link_right_wheel_joint</right_joint>
      <wheel_separation>0.4</wheel_separation>
      <wheel_radius>0.025</wheel_radius>
=======
      <!-- joints must match your URDF joint names -->
      <left_joint>base_link_left_wheel_joint</left_joint>
      <right_joint>base_link_right_wheel_joint</right_joint>

      <!-- realistic values matching wheel geometry above -->
      <wheel_separation>0.40</wheel_separation>
      <wheel_radius>0.025</wheel_radius>

>>>>>>> spawnrb2
      <odom_publish_frequency>20</odom_publish_frequency>
      <topic>cmd_vel</topic>
      <odom_topic>odom</odom_topic>
      <tf_topic>tf</tf_topic>
      <frame_id>odom</frame_id>
      <child_frame_id>base_link</child_frame_id>
    </plugin>
  </gazebo>

<<<<<<< HEAD
  <!-- Gazebo tags - Laser scan and link -->
  <gazebo reference="joint_laser_scan_chassis">
    <preserveFixedJoint>true</preserveFixedJoint>
  </gazebo>

  <!-- Laser scan joint and link (single, corrected copy) -->
  <joint name="joint_laser_scan_chassis" type="fixed">
    <origin rpy="0 0 0" xyz="0.8 0 0.3" />
    <parent link="base_link" />
    <child link="front_laser" />
  </joint>

=======
>>>>>>> spawnrb2
</robot>
